<?xml version="1.0" encoding="utf-8"?>
<!-- This URDF was automatically created by SolidWorks to URDF Exporter! Originally created by Stephen Brawner (brawner@gmail.com) 
     Commit Version: 1.5.1-0-g916b5db  Build Version: 1.5.7152.31018
     For more information, please see http://wiki.ros.org/sw_urdf_exporter -->
<robot
  name="ackerman">
  <link
    name="base_link">
    <inertial>
      <origin
        xyz="-0.025893 -0.0071223 0.20147"
        rpy="0 0 0" />
      <mass
        value="0.2" />
      <inertia
        ixx="1"
        ixy="0"
        ixz="0"
        iyy="1"
        iyz="0"
        izz="1" />
    </inertial>
    <visual>
      <origin
        xyz="0 0 0"
        rpy="0 0 0" />
      <geometry>
        <mesh
          filename="package://ackerman/meshes/base_link.STL" />
      </geometry>
      <material
        name="">
        <color
          rgba="1 1 1 1" />
      </material>
    </visual>
    <collision>
      <origin
        xyz="0 0 0"
        rpy="0 0 0" />
      <geometry>
        <mesh
          filename="package://ackerman/meshes/base_link.STL" />
      </geometry>
    </collision>
  </link>
  <link
    name="center_link">
    <inertial>
      <origin
        xyz="-0.026983 -0.0019971 -4.2365E-09"
        rpy="0 0 0" />
      <mass
        value="1" />
      <inertia
        ixx="1"
        ixy="0"
        ixz="0"
        iyy="1"
        iyz="0"
        izz="1" />
    </inertial>
    <visual>
      <origin
        xyz="0 0 0"
        rpy="0 0 0" />
      <geometry>
        <mesh
          filename="package://ackerman/meshes/center_link.STL" />
      </geometry>
      <material
        name="">
        <color
          rgba="1 1 1 1" />
      </material>
    </visual>
    <collision>
      <origin
        xyz="0 0 0"
        rpy="0 0 0" />
      <geometry>
        <mesh
          filename="package://ackerman/meshes/center_link.STL" />
      </geometry>
    </collision>
  </link>
  <joint
    name="slide_joint"
    type="prismatic">
    <origin
      xyz="0 -0.225 0.035738"
      rpy="-1.5708 0 0" />
    <parent
      link="base_link" />
    <child
      link="center_link" />
    <axis
      xyz="1 0 0" />
    <limit
      lower="-0.05"
      upper="0.05"
      effort="0.1"
      velocity="0.1" />
    <dynamics
      friction="0" />
  </joint>
  <link
    name="arm_link1_left">
    <inertial>
      <origin
        xyz="-0.0464531889391942 -0.00630899693899573 -0.0106194174430337"
        rpy="0 0 0" />
      <mass
        value="0.024" />
      <inertia
        ixx="1"
        ixy="0"
        ixz="0"
        iyy="1"
        iyz="0"
        izz="1" />
    </inertial>
    <visual>
      <origin
        xyz="0 0 0"
        rpy="0 0 0" />
      <geometry>
        <mesh
          filename="package://ackerman/meshes/arm_link1_left.STL" />
      </geometry>
      <material
        name="">
        <color
          rgba="1 1 1 1" />
      </material>
    </visual>
    <collision>
      <origin
        xyz="0 0 0"
        rpy="0 0 0" />
      <geometry>
        <mesh
          filename="package://ackerman/meshes/arm_link1_left.STL" />
      </geometry>
    </collision>
  </link>
  <joint
    name="left_joint_1"
    type="continuous">
    <origin
      xyz="-0.10198 -0.02 0"
      rpy="3.1416 0 0" />
    <parent
      link="center_link" />
    <child
      link="arm_link1_left" />
    <axis
      xyz="0 1 0" />
    <dynamics
      friction="0" />
  </joint>
  <link
    name="arm_link2_left">
    <inertial>
      <origin
        xyz="-0.012086 -0.0059561 -0.043719"
        rpy="0 0 0" />
      <mass
        value="0.065717" />
      <inertia
        ixx="1"
        ixy="0"
        ixz="0"
        iyy="1"
        iyz="0"
        izz="1" />
    </inertial>
    <visual>
      <origin
        xyz="0 0 0"
        rpy="0 0 0" />
      <geometry>
        <mesh
          filename="package://ackerman/meshes/arm_link2_left.STL" />
      </geometry>
      <material
        name="">
        <color
          rgba="1 1 1 1" />
      </material>
    </visual>
    <collision>
      <origin
        xyz="0 0 0"
        rpy="0 0 0" />
      <geometry>
        <mesh
          filename="package://ackerman/meshes/arm_link2_left.STL" />
      </geometry>
    </collision>
  </link>
  <joint
    name="left_joint2"
    type="continuous">
    <origin
      xyz="-0.069826 -0.02 -0.015962"
      rpy="0 0 0" />
    <parent
      link="arm_link1_left" />
    <child
      link="arm_link2_left" />
    <axis
      xyz="0 -1 0" />
    <dynamics
      friction="0" />
  </joint>
  <link
    name="left_flag_link">
    <inertial>
      <origin
        xyz="-0.00071532 0.009292 0.00024226"
        rpy="0 0 0" />
      <mass
        value="0.001" />
      <inertia
        ixx="1"
        ixy="0"
        ixz="0"
        iyy="1"
        iyz="0"
        izz="1" />
    </inertial>
    <visual>
      <origin
        xyz="0 0 0"
        rpy="0 0 0" />
      <geometry>
        <mesh
          filename="package://ackerman/meshes/left_flag_link.STL" />
      </geometry>
      <material
        name="">
        <color
          rgba="1 1 1 1" />
      </material>
    </visual>
    <collision>
      <origin
        xyz="0 0 0"
        rpy="0 0 0" />
      <geometry>
        <mesh
          filename="package://ackerman/meshes/left_flag_link.STL" />
      </geometry>
    </collision>
  </link>
  <joint
    name="left_fixed"
    type="fixed">
    <origin
      xyz="-0.018158 -0.03 -0.068827"
      rpy="0 0.6645 3.1416" />
    <parent
      link="arm_link2_left" />
    <child
      link="left_flag_link" />
    <axis
      xyz="0 0 0" />
  </joint>
  <link
    name="arm_link1_right">
    <inertial>
      <origin
        xyz="0.046346 -0.006309 -0.011078"
        rpy="0 0 0" />
      <mass
        value="0.024" />
      <inertia
        ixx="1"
        ixy="0"
        ixz="0"
        iyy="1"
        iyz="0"
        izz="1" />
    </inertial>
    <visual>
      <origin
        xyz="0 0 0"
        rpy="0 0 0" />
      <geometry>
        <mesh
          filename="package://ackerman/meshes/arm_link1_right.STL" />
      </geometry>
      <material
        name="">
        <color
          rgba="1 1 1 1" />
      </material>
    </visual>
    <collision>
      <origin
        xyz="0 0 0"
        rpy="0 0 0" />
      <geometry>
        <mesh
          filename="package://ackerman/meshes/arm_link1_right.STL" />
      </geometry>
    </collision>
  </link>
  <joint
    name="right_joint1"
    type="continuous">
    <origin
      xyz="0.048017 -0.02 0"
      rpy="3.1416 0 0" />
    <parent
      link="center_link" />
    <child
      link="arm_link1_right" />
    <axis
      xyz="0 1 0" />
    <dynamics
      friction="0" />
  </joint>
  <link
    name="arm_link2_right">
    <inertial>
      <origin
        xyz="0.013568 -0.0059561 -0.043282"
        rpy="0 0 0" />
      <mass
        value="0.065717" />
      <inertia
        ixx="1"
        ixy="0"
        ixz="0"
        iyy="1"
        iyz="0"
        izz="1" />
    </inertial>
    <visual>
      <origin
        xyz="0 0 0"
        rpy="0 0 0" />
      <geometry>
        <mesh
          filename="package://ackerman/meshes/arm_link2_right.STL" />
      </geometry>
      <material
        name="">
        <color
          rgba="1 1 1 1" />
      </material>
    </visual>
    <collision>
      <origin
        xyz="0 0 0"
        rpy="0 0 0" />
      <geometry>
        <mesh
          filename="package://ackerman/meshes/arm_link2_right.STL" />
      </geometry>
    </collision>
  </link>
  <joint
    name="right_joint2"
    type="continuous">
    <origin
      xyz="0.069664 -0.02 -0.016653"
      rpy="0 0 0" />
    <parent
      link="arm_link1_right" />
    <child
      link="arm_link2_right" />
    <axis
      xyz="0 -1 0" />
    <dynamics
      friction="0" />
  </joint>
  <link
    name="right_flag_link">
    <inertial>
      <origin
        xyz="-0.00072482 0.009292 0.00026181"
        rpy="0 0 0" />
      <mass
        value="0.001" />
      <inertia
        ixx="1"
        ixy="0"
        ixz="0"
        iyy="1"
        iyz="0"
        izz="1" />
    </inertial>
    <visual>
      <origin
        xyz="0 0 0"
        rpy="0 0 0" />
      <geometry>
        <mesh
          filename="package://ackerman/meshes/right_flag_link.STL" />
      </geometry>
      <material
        name="">
        <color
          rgba="1 1 1 1" />
      </material>
    </visual>
    <collision>
      <origin
        xyz="0 0 0"
        rpy="0 0 0" />
      <geometry>
        <mesh
          filename="package://ackerman/meshes/right_flag_link.STL" />
      </geometry>
    </collision>
  </link>
  <joint
    name="right_fixed_link"
    type="fixed">
    <origin
      xyz="0.021425 -0.03 -0.068347"
      rpy="3.1416 -0.69747 0" />
    <parent
      link="arm_link2_right" />
    <child
      link="right_flag_link" />
    <axis
      xyz="0 0 0" />
  </joint>





  <gazebo>
     <plugin name="gazebo_ros_control" filename="libgazebo_ros_control.so">
     <robotNamespace>/ackerman</robotNamespace>
     <controlPeriod>0.001</controlPeriod>
     <robotSimType>gazebo_ros_control/DefaultRobotHWSim</robotSimType>
     <legacyModeNS>true</legacyModeNS>
     </plugin>
  </gazebo>


 <transmission name="slide_joint_trans">
    <type>transmission_interface/SimpleTransmission</type>
    <joint name="slide_joint">
      <hardwareInterface>hardware_interface/PositionJointInterface</hardwareInterface>
    </joint>
    <actuator name="motor1">
      <hardwareInterface>hardware_interface/PositionJointInterface</hardwareInterface>
      <mechanicalReduction>1</mechanicalReduction>
    </actuator>
  </transmission>






</robot>
